Workbook

Sheet Levantamento Campo
B1: Prj Estande de Tiro (50 m) – 5º BIL (Amv)
B3: LEVANTAMENTO DE CAMPO
E5: Dimensões | J5: Vãos | O5: Alvenarias Adicionais
B6: Ambiente | E6: C | F6: L | G6: h | H6: e | I6: A | J6: Tipo | K6: C | L6: h | M6: e | N6: A | O6: Tipo | P6: C | Q6: h | R6: e | S6: V
E7: [m] | F7: [m] | G7: [m] | H7: [m] | I7: [m²] | K7: [m] | L7: [m] | M7: [m] | N7: [m²] | P7: [m] | Q7: [m] | R7: [m] | S7: [m³]
B8: Ambiente 1 | E8: 3 | F8: 4 | G8: 3 | H8: 0 | I8: =E8*F8 | J8: Janela | K8: 1 | L8: 1.2 | M8: 0 | N8: =K8*L8 | S8: =R8*Q8*P8
B9: Ambiente 2 | E9: 3.5 | F9: 4.5 | G9: 3 | H9: 0 | I9: =E9*F9 | N9: =K9*L9 | O9: Meia parede | P9: 0.2 | Q9: 1 | R9: 0.2 | S9: =R9*Q9*P9
B10: Ambiente 3 | E10: 4 | F10: 5 | G10: 3.2 | H10: 0 | I10: =E10*F10 | J10: Porta | K10: 0.9 | L10: 2.1 | M10: 0 | N10: =K10*L10 | S10: =R10*Q10*P10
B11: Ambiente 4 | E11: 2.5 | F11: 3 | G11: 3 | H11: 0 | I11: =E11*F11 | N11: =K11*L11 | S11: =R11*Q11*P11
B12: Ambiente 5 | E12: 3.2 | F12: 3.8 | G12: 3 | H12: 0 | I12: =E12*F12 | J12: Janela | K12: 1.2 | L12: 1 | M12: 0 | N12: =K12*L12 | S12: =R12*Q12*P12
B13: Ambiente 6 | E13: 3 | F13: 3.5 | G13: 3 | H13: 0 | I13: =E13*F13 | N13: =K13*L13 | O13: Muro | P13: 0.3 | Q13: 2 | R13: 0.3 | S13: =R13*Q13*P13
B14: Ambiente 7 | E14: 4.2 | F14: 4 | G14: 3.2 | H14: 0 | I14: =E14*F14 | J14: Vitrô | K14: 2 | L14: 1.2 | M14: 0 | N14: =K14*L14 | S14: =R14*Q14*P14
B15: Ambiente 8 | E15: 2.8 | F15: 3.2 | G15: 3 | H15: 0 | I15: =E15*F15 | N15: =K15*L15 | S15: =R15*Q15*P15
B16: Ambiente 9 | E16: 3.6 | F16: 4.2 | G16: 3 | H16: 0 | I16: =E16*F16 | J16: Porta | K16: 0.9 | L16: 2 | M16: 0 | N16: =K16*L16 | S16: =R16*Q16*P16
B17: Ambiente 10 | E17: 3.1 | F17: 3.7 | G17: 3 | H17: 0 | I17: =E17*F17 | N17: =K17*L17 | S17: =R17*Q17*P17
B18: Ambiente 11 | E18: 4 | F18: 6 | G18: 3.2 | H18: 0 | I18: =E18*F18 | N18: =K18*L18 | S18: =R18*Q18*P18
B19: Ambiente 12 | E19: 2.5 | F19: 4 | G19: 3 | H19: 0 | I19: =E19*F19 | N19: =K19*L19 | S19: =R19*Q19*P19
B20: Ambiente 13 | E20: 3 | F20: 5 | G20: 3 | H20: 0 | I20: =E20*F20 | N20: =K20*L20 | S20: =R20*Q20*P20
B21: Ambiente 14 | E21: 3.3 | F21: 4.4 | G21: 3 | H21: 0 | I21: =E21*F21 | N21: =K21*L21 | S21: =R21*Q21*P21
B22: Ambiente 15 | E22: 3.7 | F22: 4.1 | G22: 3 | H22: 0 | I22: =E22*F22 | N22: =K22*L22 | S22: =R22*Q22*P22
B23: Ambiente 16 | E23: 2.9 | F23: 3.9 | G23: 3 | H23: 0 | I23: =E23*F23 | N23: =K23*L23 | S23: =R23*Q23*P23
B24: Ambiente 17 | E24: 4.5 | F24: 5 | G24: 3.2 | H24: 0 | I24: =E24*F24 | N24: =K24*L24 | S24: =R24*Q24*P24
B25: Ambiente 18 | E25: 3.8 | F25: 4.2 | G25: 3 | H25: 0 | I25: =E25*F25 | N25: =K25*L25 | S25: =R25*Q25*P25
I26: =E26*F26 | N26: =K26*L26 | S26: =R26*Q26*P26
I27: =E27*F27 | N27: =K27*L27 | S27: =R27*Q27*P27
E30: Pilar | I30: Viga | M30: Laje
B31: Ambiente | E31: C | F31: L | G31: h | H31: A | I31: C | J31: h | K31: e | L31: A | M31: C | N31: L | O31: e | P31: A
E32: [m] | F32: [m] | G32: [m] | H32: [m²] | I32: [m] | J32: [m] | K32: [m] | L32: [m²] | M32: [m] | N32: [m] | O32: [m] | P32: [m²]
B33: =B8 | E33: 0.3 | F33: 0.3 | G33: 3 | H33: =E33*F33 | I33: 0.2 | J33: 0.4 | K33: 0 | L33: =I33*J33 | M33: 5 | N33: 4 | O33: 0.12 | P33: =O33*N33*M33
B34: =B9 | E34: 0.25 | F34: 0.25 | G34: 3 | H34: =E34*F34 | L34: =I34*J34 | M34: 4 | N34: 5 | O34: 0.1 | P34: =O34*N34*M34
B35: =B10 | E35: 0.35 | F35: 0.35 | G35: 3.2 | H35: =E35*F35 | I35: 0.25 | J35: 0.4 | K35: 0 | L35: =I35*J35 | P35: =O35*N35*M35
B36: =B11 | H36: =E36*F36 | I36: 0.22 | J36: 0.35 | K36: 0 | L36: =I36*J36 | M36: 3 | N36: 3.5 | O36: 0.1 | P36: =O36*N36*M36
B37: =B12 | E37: 0.3 | F37: 0.3 | G37: 3 | H37: =E37*F37 | L37: =I37*J37 | P37: =O37*N37*M37
B38: =B13 | E38: 0.28 | F38: 0.28 | G38: 3 | H38: =E38*F38 | L38: =I38*J38 | P38: =O38*N38*M38
B39: =B14 | H39: =E39*F39 | L39: =I39*J39 | M39: 6 | N39: 5 | O39: 0.12 | P39: =O39*N39*M39
B40: =B15 | H40: =E40*F40 | I40: 0.2 | J40: 0.4 | K40: 0 | L40: =I40*J40 | P40: =O40*N40*M40
B41: =B16 | E41: 0.3 | F41: 0.3 | G41: 3 | H41: =E41*F41 | L41: =I41*J41 | P41: =O41*N41*M41
B42: =B17 | H42: =E42*F42 | L42: =I42*J42 | P42: =O42*N42*M42
B43: =B18 | H43: =E43*F43 | L43: =I43*J43 | P43: =O43*N43*M43
B44: =B19 | H44: =E44*F44 | L44: =I44*J44 | P44: =O44*N44*M44
...

Sheet Serviços Preliminares
B1: ='Levantamento Campo'!B1
A3: 1. | B3: SERVIÇOS PRELIMINARES
A5: 1.1 | B5: Limpeza Inicial
B7: Limpeza
B8: A [m²]
B9: =SUM('Levantamento Campo'!G9:G28)
A11: 1.2 | B11: Implantação de Canteiro de Obra
A17: 1.3 | B17: Alocação de Contêineres
A23: 1.4 | B23: Alocação de Banheiros Químicos
A29: 1.5 | B29: Alocação de Andaimes
A35: 1.6 | B35: Interdições no Local da Obra e Adjacências
B37: Fase | C37: Ambiente | E37: Local | G37: A [m²]
B38: Inicial | C38: Ambiente 1 | E38: Área externa
B39: Segurança | C39: Ambiente 2 | E39: Corredor principal
F42: Total | G42: =SUM(G38:G41)
A44: 1.7 | B44: Remoções | AG44: Recolocações
E46: Elétrica/SPDA/Rede | O46: Água Fria/Água Pluvial/Esgoto/Pressurizadas/Contra Incêndio | X46: Esquadrias | Z46: Telhados | AC46: Equipamentos/Acessórios | AG46: Equipamentos/Acessórios
B47: Ambiente | E47: Condulete | F47: Tomadas | G47: Interruptor | H47: Luminária | I47: Dutos | J47: Cabos | K47: Captação | L47: Aterra/o | M47: Quadros | N47: Postes | O47: Cavalete | P47: Reservat | Q47: Registros | R47: Válvulas | S47: Torneiras | T47: Dutos | U47: Calhas | V47: Caixas | W47: Drenos | X47: Portas | Y47: Janelas | Z47: Telha | AA47: Trama | AB47: Tesoura | AC47: Item | AE47: Qtd | AG47: Item | AI47: Qtd
E48: [m] | F48: [Un] | G48: [Un] | H48: [Un] | I48: [m] | J48: [m] | K48: [m] | L48: [m] | M48: [Un] | N48: [Un] | O48: [Un] | P48: [Un] | Q48: [Un] | R48: [Un] | S48: [Un] | T48: [m] | U48: [m] | V48: [Un] | W48: [Un] | X48: [m²] | Y48: [m²] | Z48: [m²] | AA48: [m²] | AB48: [Un] | AE48: [Un] | AI48: [Un]
B49: Ambiente 1 | E49: 2 | F49: 6 | G49: 2 | H49: 4 | I49: 12 | J49: 120 | K49: Parcial | L49: 5 | M49: 1 | N49: 0 | O49: 1 | P49: Cisterna | Q49: 2 | R49: 1 | S49: 3 | T49: 20 | U49: PVC | V49: 1 | W49: 0 | X49: 2 | Y49: 3 | Z49: Cerâmica | AA49: 12 | AB49: 1 | AC49: Ar Condicionado | AE49: 1
B50: Ambiente 2 | E50: 1 | F50: 4 | G50: 1 | H50: 2 | I50: 8 | J50: 80 | K50: Nenhuma | L50: 0 | M50: 1 | N50: 0 | O50: 0 | P50: Nenhum | Q50: 1 | R50: 0 | S50: 1 | T50: 8 | U50: Metal | V50: 0 | W50: 1 | X50: 1 | Y50: 2 | Z50: Fibra | AA50: 8 | AB50: 0 | AC50: Ventilador | AE50: 2
B51: ='Levantamento Campo'!B10
B52: ='Levantamento Campo'!B11
B53: ='Levantamento Campo'!B12
B54: ='Levantamento Campo'!B13
B55: ='Levantamento Campo'!B14
B56: ='Levantamento Campo'!B15
B57: ='Levantamento Campo'!B16
B58: ='Levantamento Campo'!B17
B59: ='Levantamento Campo'!B18
B60: ='Levantamento Campo'!B19
B61: ='Levantamento Campo'!B20
B62: ='Levantamento Campo'!B21
... B68: ='Levantamento Campo'!B27
B69: Total | E69: =SUM(E49:E68) | F69: =SUM(F49:F68) | G69: =SUM(G49:G68) | H69: =SUM(H49:H68) | I69: =SUM(I49:I68) | J69: =SUM(J49:J68) | K69: =SUM(K49:K68) | L69: =SUM(L49:L68) | ... AB69: =SUM(AB49:AB68) | AE69: =SUM(AE49:AE68)
A71: 1.8 | B71: Demolições
E73: Piso | F73: Rodapé | G73: Azulejo | H73: Forro | I73: Alvenaria | K73: Estrutura
B74: Ambiente | I74: Tipo | J74: V | K74: Fundação | L74: Pilar | M74: Viga | N74: Laje | AI74: =SUM(AI49:AI73)
E75: [m²] | F75: [m] | G75: [m²] | H75: [m²] | J75: [m³] | K75: [m³] | L75: [m³] | M75: [m³] | N75: [m³]
B76: Ambiente 1 | E76: 12 | F76: 15 | G76: 6 | H76: 8 | I76: Tijolo | J76: 1.2 | K76: 0.5 | L76: 0.1 | M76: 0.2 | N76: 0
...

Sheet Movimento de Solo
B1: ='Levantamento Campo'!B1
A3: 2. | B3: MOVIMENTO de SOLOS
A5: 2.1 | B5: Terraplanagem
A13: 2.2 | B13: Escavações
B15: Ambiente | E15: Tipo | F15: i | G15: L | H15: C | I15: h | J15: Lastro | K15: A | L15: V
F16: [%] | G16: [m] | H16: [m] | I16: [m] | J16: [m³] | K16: [m²] | L16: [m³]
B17: Ambiente 1 | E17: Manual | F17: 0 | G17: 5 | H17: 3 | I17: 1.2 | J17: 0 | K17: 15 | L17: 18
B18: Ambiente 2 | E18: Máquina | F18: 2.5 | G18: 6 | H18: 4 | I18: 1.5 | J18: 0.2 | K18: 24 | L18: 36
B19: Ambiente 3 | E19: Máquina | F19: 1.5 | G19: 4.5 | H19: 3.5 | I19: 1.3 | J19: 0 | K19: 15.75 | L19: 20.475
B20: Ambiente 4 | E20: Manual | F20: 0 | G20: 3.5 | H20: 3 | I20: 1 | J20: 0 | K20: 10.5 | L20: 10.5
B21: Ambiente 5 | E21: Máquina | F21: 2 | G21: 5.5 | H21: 4.2 | I21: 1.4 | J21: 0 | K21: 23.1 | L21: 32.34
B22: ='Levantamento Campo'!B13
B23: ='Levantamento Campo'!B14
B24: ='Levantamento Campo'!B15
B25: ='Levantamento Campo'!B16
B26: ='Levantamento Campo'!B17
B27: ='Levantamento Campo'!B18
B28: ='Levantamento Campo'!B19
B29: ='Levantamento Campo'!B20
B30: ='Levantamento Campo'!B21
B31: ='Levantamento Campo'!B22
B32: ='Levantamento Campo'!B23
B33: ='Levantamento Campo'!B24
... B36: ='Levantamento Campo'!B27
B37: Total | J37: =SUM(J17:J36) | K37: =SUM(K17:K36) | L37: =SUM(L17:L36)
A39: 2.3 | B39: Aterros e Reaterros
B41: Ambiente | E41: i | F41: L | G41: C | H41: h | I41: A | J41: V
E42: [%] | F42: [m] | G42: [m] | H42: [m] | I42: [m²] | J42: [m³]
B43: Ambiente 3 | E43: 1 | F43: 4 | G43: 3 | H43: 0.8 | I43: 12 | J43: 9.6
B44: Ambiente 4 | E44: 0.5 | F44: 3.5 | G44: 3 | H44: 0.6 | I44: 10.5 | J44: 6.3
B45: Ambiente 5 | E45: 0.8 | F45: 5.5 | G45: 4.2 | H45: 0.5 | I45: 23.1 | J45: 11.55
B46: ='Levantamento Campo'!B11
B47: ='Levantamento Campo'!B12
B48: ='Levantamento Campo'!B13
B49: ='Levantamento Campo'!B14
B50: ='Levantamento Campo'!B15
B51: ='Levantamento Campo'!B16
B52: ='Levantamento Campo'!B17
B53: ='Levantamento Campo'!B18
B54: ='Levantamento Campo'!B19
...

Sheet Estruturas
B1: ='Levantamento Campo'!B1
A3: 3. | B3: ESTRUTURAS
A5: 3.1 | B5: Fundações
A7: 3.1.1 | B7: Sistema Viga Baldrame
E9: Peça | F9: Seção | H9: C | I9: Lastro | J9: Concreto | K9: Ferragem | L9: Estribo | M9: Forma em Madeira
B10: Ambiente | F10: L | G10: h | M10: L | N10: C | O10: A
F11: [m] | G11: [m] | H11: [m] | I11: [m³] | J11: [m³] | K11: [KgF] | L11: [KgF] | M11: [m] | N11: [m] | O11: [m²]
B12: Ambiente 1 | E12: Viga P1 | F12: 0.3 | G12: 0.5 | H12: 0.2 | I12: 0.15 | J12: 1.2 | K12: 180 | L12: 12 | M12: 2.5 | N12: 0.25 | O12: =M12*N12
O13: =M13*N13
O14: =M14*N14
O15: =M15*N15
O16: =M16*N16
O17: =M17*N17
O18: =M18*N18
O19: =M19*N19
O20: =M20*N20
O21: =M21*N21
O22: =M22*N22
O23: =M23*N23
O24: =M24*N24
... O31: =M31*N31
B32: Total | I32: =SUM(I20:I31) | J32: =SUM(J20:J31) | K32: =SUM(K20:K31) | L32: =SUM(L20:L31) | N32: =SUM(N20:N31) | O32: =SUM(O20:O31)
A34: 3.1.2 | B34: Estacas e Blocos de Coroamento
E36: Peça | F36: Valores por Peça | I36: Valores Totais | M36: Forma em Madeira
B37: Ambiente | F37: L | G37: h | H37: C | I37: Lastro | J37: Concreto | K37: Ferragem | L37: Estribo | M37: L | N37: C | O37: A Tot
F38: [m] | G38: [m] | H38: [m] | I38: [m³] | J38: [m³] | K38: [KgF] | L38: [KgF] | M38: [m] | N38: [m] | O38: [m²]
B39: Ambiente 1 | E39: Pilar P1 | F39: 0.3 | G39: 3 | H39: 0.3 | I39: 0.27 | J39: 0.9 | K39: 60 | L39: 6 | M39: 2 | N39: 0.2 | O39: =M39*N39
O40: =M40*N40
O41: =M41*N41
O42: =M42*N42
O43: =M43*N43
O44: =M44*N44
O45: =M45*N45
O46: =M46*N46
O47: =M47*N47
O48: =M48*N48
O49: =M49*N49
O50: =M50*N50
O51: =M51*N51
... O58: =M58*N58
...

Sheet Alvenarias
B1: ='Levantamento Campo'!B1
A3: 4. | B3: ALVENARIAS
A5: 4.1 | B5: Painéis
E7: Painéis em Alvenaria | K7: Painéis em Gesso Acartonado | Q7: Painéis Cobogó ou em Blocos de Vidro
B8: Ambiente | E8: Peça | F8: C | G8: L | H8: h | I8: Vãos | J8: A | K8: Peça | L8: C | M8: L | N8: h | O8: Vãos | P8: A | Q8: Peça | R8: C | S8: L | T8: h | U8: Vãos | V8: A
F9: [m] | G9: [m] | H9: [m] | I9: [m²] | J9: [m²] | L9: [m] | M9: [m] | N9: [m] | O9: [m²] | P9: [m²] | R9: [m] | S9: [m] | T9: [m] | U9: [m²] | V9: [m²]
B10: ='Levantamento Campo'!B8
B11: ='Levantamento Campo'!B9
B12: ='Levantamento Campo'!B10
B13: ='Levantamento Campo'!B11
B14: ='Levantamento Campo'!B12
B15: ='Levantamento Campo'!B13
B16: ='Levantamento Campo'!B14
B17: ='Levantamento Campo'!B15
B18: ='Levantamento Campo'!B16
B19: ='Levantamento Campo'!B17
B20: ='Levantamento Campo'!B18
B21: ='Levantamento Campo'!B19
... B29: ='Levantamento Campo'!B27
B30: Total | J30: =SUM(J10:J29) | P30: =SUM(P10:P29)
A32: 4.2 | B32: Vergas e Contra Vergas
B34: Ambiente | E34: Peça | F34: Qtd | H34: L | I34: C | J34: h | K34: Engasta/o | L34: Concreto | M34: Ferragem
F35: Verga | G35: C Verga | H35: [m] | I35: [m] | J35: [m] | K35: [m] | L35: [m³] | M35: [KgF]
B36: ='Levantamento Campo'!B8
B37: ='Levantamento Campo'!B9
B38: ='Levantamento Campo'!B10
B39: ='Levantamento Campo'!B11
B40: ='Levantamento Campo'!B12
B41: ='Levantamento Campo'!B13
B42: ='Levantamento Campo'!B14
B43: ='Levantamento Campo'!B15
B44: ='Levantamento Campo'!B16
B45: ='Levantamento Campo'!B17
B46: ='Levantamento Campo'!B18
B47: ='Levantamento Campo'!B19
... B55: ='Levantamento Campo'!B27
B56: Total | F56: =SUM(F36:F55) | G56: =SUM(G36:G55) | L56: =SUM(L36:L55) | M56: =SUM(M36:M55)
A58: 4.3 | B58: Guias, Calçadas e Passeios
E60: Guias | J60: Calçadas e passeios
B61: Ambiente | E61: Local | F61: L | G61: h | H61: C | I61: Concreto | J61: Local | K61: L | L61: h | M61: e | N61: C | O61: A | P61: Concreto
...

Sheet Acabamentos
B1: ='Levantamento Campo'!B1
E4: Pisos | L4: Soleiras | P4: Rodapés
E5: Tipo | F5: Dimensões | J5: Placa Cerâmica | L5: Tipo | M5: Dimensões | P5: Tipo | Q5: Dimensões
B6: Ambiente | F6: e | G6: C | H6: L | I6: A | J6: C | K6: L | M6: e | N6: C | O6: L | Q6: h | R6: C | S6: L | T6: A
F7: [m] | G7: [m] | H7: [m] | I7: [m²] | J7: [m] | K7: [m] | M7: [m] | N7: [m] | O7: [m] | Q7: [m] | R7: [m] | S7: [m] | T7: [m²]
B8: Ambiente 1 | E8: Cerâmica | F8: 0.01 | G8: 0.3 | H8: 0.3 | I8: 9 | J8: 0.3 | K8: 0.3 | L8: Granito | M8: 0.02 | N8: 0.1 | O8: 0.9 | P8: PVC | Q8: 0.08 | R8: 0.01 | S8: 3 | T8: 0.24
B9: Ambiente 2 | E9: Porcelanato | F9: 0.01 | G9: 0.6 | H9: 0.6 | I9: 36 | J9: 0.6 | K9: 0.6 | L9: Alvenaria | M9: 0.02 | N9: 0.12 | O9: 1 | P9: Madeira | Q9: 0.1 | R9: 0.02 | S9: 4 | T9: 0.4
B28: Total | I28: =SUM(I8:I27) | N28: =SUM(N8:N27) | R28: =SUM(R8:R27)
E31: Azulejos e Rodabancas | L31: Peitoris | P31: Forros
B32: Ambiente | E32: Tipo | F32: Dimensões | J32: Placa | L32: Tipo | M32: Dimensões | P32: Tipo | Q32: Dimensões | T32: Placa
F33: e | G33: h | H33: CTot | I33: A | J33: L | K33: C | M33: e | N33: L | O33: C | Q33: L | R33: C | S33: A | T33: L | U33: C
F34: [m] | G34: [m] | H34: [m] | I34: [m²] | J34: [m] | K34: [m] | M34: [m] | N34: [m] | O34: [m] | Q34: [m] | R34: [m] | S34: [m²] | T34: [m] | U34: [m]
B35: Ambiente 1 | E35: Cerâmica | F35: 0.01 | G35: 0.2 | H35: 0.3 | I35: 6 | J35: 0.3 | K35: 0.2 | L35: Concreto | M35: 0.02 | N35: 0.5 | O35: 1.2 | P35: Drywall | Q35: 2.4 | R35: 1.2 | S35: 2.88 | T35: 1.2 | U35: 0.6
B55: Total | I55: =SUM(I35:I54) | N55: =SUM(N35:N54) | R55: =SUM(R35:R54)
B58: Ambiente | E58: Emassamento | I58: Lixamento | M58: Selamento | Q58: Pintura Acrílica | U58: Pintura Esmalte
E59: h | F59: Per | G59: A [m²] | I59: h | J59: Per | K59: A [m²] | M59: h | N59: Per | O59: A [m²] | Q59: A [m²] | U59: A [m²]
E60: [m] | F60: [m] | G60: Parede | H60: Teto | I60: [m] | J60: [m] | K60: Parede | L60: Teto | M60: [m] | N60: [m] | O60: Parede | P60: Teto | Q60: Parede | R60: Teto | S60: Piso | T60: Pilar | U60: Portas | V60: Janelas | W60: Grades
B61: Ambiente 1 | E61: 0.02 | F61: 15 | G61: 30 | H61: 20 | I61: 0.005 | J61: 10 | K61: 30 | L61: 20 | M61: 0.003 | N61: 5 | O61: 30 | P61: 20 | Q61: 30 | R61: 20 | S61: 0 | T61: 5 | U61: 6 | V61: 4 | W61: 2
B81: Total | I81: =SUM(I61:I80) | N81: =SUM(N61:N80) | Q81: =SUM(Q61:Q80) | R81: =SUM(R61:R80) | S81: =SUM(S61:S80) | T81: =SUM(T61:T80) | U81: =SUM(U61:U80) | V81: =SUM(V61:V80) | W81: =SUM(W61:W80)
E84: Portas e Alçapões | K84: Janelas e Visores | Q84: Telas | U84: Vidros | Y84: Venezianas Industriais | AD84: Protetores de Canto | AG84: Protetores de Parede | AJ84: Grades
B85: Ambiente | E85: P/A | F85: Qtd | G85: L | H85: h | I85: e | J85: A | K85: J/V | L85: Qtd | M85: L | N85: h | O85: e | P85: A | Q85: L | R85: h | S85: Qtd | T85: A [m2] | U85: L | V85: h | W85: Qtd | X85: A [m2] | Y85: Peça | Z85: L | AA85: h | AB85: Qtd | AC85: A [m2] | AD85: L | AE85: e | AF85: C | AG85: L | AH85: e | AI85: C | AJ85: Tipo | AK85: A | AL85: Malha | AM85: e | AN85: Afastamento [cm]
G86: [cm] | H86: [cm] | I86: [cm] | J86: [m2] | M86: [cm] | N86: [cm] | O86: [cm] | P86: [m2] | Q86: [cm] | R86: [cm] | U86: [cm] | V86: [cm] | Z86: [cm] | AA86: [cm] | AD86: [cm] | AE86: [mm] | AF86: [m] | AG86: [cm] | AH86: [mm] | AI86: [m] | AK86: [m2] | AL86: [cm] | AM86: [mm] | AN86: Janela | AO86: Alvenaria
B87: Ambiente 1 | E87: P1 | F87: 2 | G87: 0.9 | H87: 2.1 | I87: 0.04 | J87: 3.78 | K87: J1 | L87: 2 | M87: 1.2 | N87: 1 | O87: 0.04 | P87: 2.4 | Q87: 1 | R87: 1 | S87: 1 | T87: 1 | U87: 1.2 | V87: 1 | W87: 2 | X87: 2.4 | Y87: V1 | Z87: 1 | AA87: 0.8 | AB87: 1 | AC87: 0.8 | AD87: 0.2 | AE87: 0.02 | AF87: 0.01 | AG87: 2 | AH87: 0.03 | AI87: 0.02 | AJ87: Aço | AK87: 10 | AL87: 10x10 | AM87: 0.02 | AN87: 0.15 | AO87: 0.1
B107: Total | I107: =SUM(I87:I106) | N107: =SUM(N87:N106) | T107: =SUM(T87:T106) | X107: =SUM(X87:X106) | AC107: =SUM(AC87:AC106)
E110: Acessórios | K110: Barras de Apoio | O110: Corrimãos e Guarda-Corpos
B111: Ambiente | E111: Bacias Sanitárias | F111: Mictórios | G111: Lavatórios | H111: Cubas | I111: Tanques | J111: Torneiras | K111: Qtd | L111: C | M111: ø | N111: h Piso | O111: Qtd | P111: C | Q111: ø | R111: h Piso
L112: [m] | M112: [mm] | N112: [m] | P112: [m] | Q112: [mm] | R112: [m]
B113: Ambiente 1 | E113: 2 | F113: 0 | G113: 2 | H113: 1 | I113: 1 | J113: 5 | K113: 2 | L113: 1.2 | M113: 0.03 | N113: 0.8 | O113: 1 | P113: 2.5 | Q113: 0.04 | R113: 0.9
B133: Total | I133: =SUM(I113:I132) | N133: =SUM(N113:N132)
E136: Bancadas e Pias | P136: Divisórias | X136: Boxes
B137: Ambiente | E137: Dimensões | G137: Tampo | J137: Frontão | M137: Saia | P137: Tipo | Q137: Qtd | R137: Peça | U137: Portas | X137: Tipo | Y137: Qtd | Z137: Peça
E138: A | F138: h | G138: L | H138: C | I138: e | J138: L | K138: C | L138: e | M138: L | N138: C | O138: e | R138: C | S138: h | T138: A | U138: L | V138: h | W138: A | Z138: L | AA138: C | AB138: e | AC138: Sobreposição | AD138: A
E139: [m²] | F139: [m] | G139: [m] | H139: [m] | I139: [m] | J139: [m] | K139: [m] | L139: [m] | M139: [m] | N139: [m] | O139: [m] | R139: [m] | S139: [m] | T139: [m²] | U139: [m] | V139: [m] | W139: [m²] | Z139: [cm] | AA139: [cm] | AB139: [mm] | AC139: [cm] | AD139: [m²]
B140: Ambiente 1 | E140: 1.2 | F140: 0.9 | G140: 1.2 | H140: 0.6 | I140: 0.03 | J140: 1.2 | K140: 0.2 | L140: 0.02 | M140: 1.2 | N140: 0.6 | O140: 0.02 | P140: PVC | Q140: 2 | R140: 0.6 | S140: 2 | T140: 1.2 | U140: 0.8 | V140: 2.1 | W140: 1.68 | X140: Vidro | Y140: 1 | Z140: 0.8 | AA140: 0.9 | AB140: 0.01 | AC140: 0.05 | AD140: 0.72
B160: Total | I160: =SUM(I140:I159) | N160: =SUM(N140:N159) | T160: =SUM(T140:T159) | W160: =SUM(W140:W159) | AD160: =SUM(AD140:AD159)
E163: Mobiliário
B164: Ambiente | E164: Tipo | F164: Dimensões [m] | I164: A
F165: h | G165: L | H165: C | I165: [m²]
B166: Ambiente 1 | E166: Balcão | F166: 0.9 | G166: 1.2 | H166: 0.6 | I166: 0.72
B186: Total | I186: =SUM(I166:I185)

Sheet Inst Hidráulicas
B1: ='Levantamento Campo'!B1

Sheet Inst Elétricas
B1: ='Levantamento Campo'!B1
B3: CIRCUITOS AÉREOS
F4: Cabeamentos | N4: Postes | P4: Cruzetas | R4: Suportes | T4: Isoladores
B5: Local | E5: Circuito | F5: Qtd Cabos | G5: C [m] / A [mm²] | N5: ø | O5: C | P5: L | Q5: C | R5: L | S5: C | T5: ø | U5: C
G6: 1.5 | H6: 2.5 | I6: 4 | J6: 10 | K6: 16 | L6: 25 | M6: 100 | N6: [m] | O6: [m] | P6: [m] | Q6: [m] | R6: [m] | S6: [m] | T6: [m] | U6: [m]
B24: Total | G24: =SUM(G7:G23) | H24: =SUM(H7:H23) | I24: =SUM(I7:I23) | J24: =SUM(J7:J23) | K24: =SUM(K7:K23) | L24: =SUM(L7:L23) | M24: =SUM(M7:M23) | O24: =SUM(O7:O23) | Q24: =SUM(Q7:Q23) | S24: =SUM(S7:S23) | U24: =SUM(U7:U23)
B27: CIRCUITOS SUBTERRÂNEOS
N28: Eletroduto
F29: Cabeamento | N29: Metálico | P29: Corrugado | R29: PVC Liso
B30: Local | E30: Circuito | F30: Qtd Cabos | G30: C [m] / A [mm²] | N30: DN | O30: C | P30: DN | Q30: C | R30: DN | S30: C
G31: 1.5 | H31: 2.5 | I31: 4 | J31: 10 | K31: 16 | L31: 25 | M31: 100 | N31: [mm] | O31: [m] | P31: [mm] | Q31: [m] | R31: [mm] | S31: [m]
B49: Total | G49: =SUM(G32:G48) | H49: =SUM(H32:H48) | I49: =SUM(I32:I48) | J49: =SUM(J32:J48) | K49: =SUM(K32:K48) | L49: =SUM(L32:L48) | M49: =SUM(M32:M48) | O49: =SUM(O32:O48) | Q49: =SUM(Q32:Q48) | S49: =SUM(S32:S48)
B52: CIRCUITOS INTERNOS
F54: Quadros de Energia | K54: Cabeamentos | P54: Dutos | AL54: Aterramento
B55: Local | E55: Circuito | F55: Tipo | G55: Qtd Disjuntores | K55: A [mm²] | P55: Eletrocalha | U55: Eletroduto | AL55: Haste | AO55: Caixa Inspeção
K56: 1.5 | L56: 2.5 | M56: 4 | N56: 10 | O56: 16 | P56: L | Q56: h | R56: C | S56: Septo Elétrica | T56: Septo Lógica | U56: DN | V56: C | W56: Conduletes | AF56: Tomadas | AH56: Interruptores | AJ56: Luminárias | AL56: DN | AM56: C | AN56: Qtd | AO56: Qtd | AP56: DN | AQ56: h
K57: C [m] | L57: C [m] | M57: C [m] | N57: C [m] | O57: C [m] | P57: [cm] | Q57: [cm] | R57: [m] | S57: [cm] | T57: [cm] | U57: [mm] | V57: [m] | W57: B | X57: C | Y57: E | Z57: LL | AA57: LR | AB57: LB | AC57: TB | AD57: T | AE57: X | AF57: Tipo | AG57: Qtd | AH57: Tipo | AI57: Qtd | AJ57: Tipo | AK57: Qtd | AL57: [pol] | AM57: [m] | AP57: [pol] | AQ57: [mm]
B75: Total | H75: =SUM(H58:H74) | I75: =SUM(I58:I74) | J75: =SUM(J58:J74) | K75: =SUM(K58:K74) | L75: =SUM(L58:L74) | M75: =SUM(M58:M74) | N75: =SUM(N58:N74) | O75: =SUM(O58:O74) | R75: =SUM(R58:R74) | V75: =SUM(V58:V74) | W75: =SUM(W58:W74) | X75: =SUM(X58:X74) | Y75: =SUM(Y58:Y74) | Z75: =SUM(Z58:Z74) | AA75: =SUM(AA58:AA74) | AB75: =SUM(AB58:AB74) | AC75: =SUM(AC58:AC74) | ... AE75: =SUM(AE58:AE74) | AG75: =SUM(AG58:AG74) | AI75: =SUM(AI58:AI74) | AK75: =SUM(AK58:AK74) | AM75: =SUM(AM58:AM74) | AN75: =SUM(AN58:AN74) | AO75: =SUM(AO58:AO74)

Sheet Inst de Telefonia e Rede
B1: ='Levantamento Campo'!B1
F4: Quadros de Rede | H4: Cabeamentos | M4: Dutos | AE4: Aterramento
E5: Circuito | F5: Tipo | G5: Qtd | H5: Rede | I5: Patch Cord | J5: Câmera | K5: TV | L5: Telefonia | M5: Eletrocalha | P5: Septo | R5: Eletroduto | AE5: Haste | AH5: Caixa Inspeção
B6: Local | M6: L | N6: h | O6: C | P6: Elétrica | Q6: Lógica | R6: DN | S6: C | T6: Conduletes | AC6: Tomadas | AE6: DN | AF6: C | AG6: Qtd | AH6: Qtd | AI6: DN | AJ6: h
H7: C [m] | I7: C [m] | J7: C [m] | K7: C [m] | L7: C [m] | M7: [cm] | N7: [cm] | O7: [m] | P7: [cm] | Q7: [cm] | R7: [mm] | S7: [m] | T7: B | U7: C | V7: E | W7: LL | X7: LR | Y7: LB | Z7: TB | AA7: T | AB7: X | AC7: RJ 45 | AD7: Keystone | AE7: [pol] | AF7: [m] | AI7: [pol] | AJ7: [mm]
B25: Total | H25: =SUM(H8:H24) | I25: =SUM(I8:I24) | J25: =SUM(J8:J24) | K25: =SUM(K8:K24) | L25: =SUM(L8:L24) | O25: =SUM(O8:O24) | S25: =SUM(S8:S24) | T25: =SUM(T8:T24) | U25: =SUM(U8:U24) | V25: =SUM(V8:V24) | W25: =SUM(W8:W24) | X25: =SUM(X8:X24) | Y25: =SUM(Y8:Y24) | Z25: =SUM(Z8:Z24) | ... AB25: =SUM(AB8:AB24) | AD25: =SUM(AD8:AD24) | AF25: =SUM(AF8:AF24) | AG25: =SUM(AG8:AG24) | AH25: =SUM(AH8:AH24)

Sheet Inst Mecânicas
B1: ='Levantamento Campo'!B1
E4: Ar Condicionado | K4: Ventilador | M4: Exaustor
E5: Qtd | F5: Pot | G5: Mat Complementar | K5: Qtd | L5: Tipo | M5: Qtd | N5: Tipo
G6: Dutos | I6: Cabo Elétrico | J6: Gás Refrig
B7: Ambiente | G7: Refrig | H7: Dreno
F8: [BTU] | G8: [m] | H8: [m] | I8: [KgF] | J8: [m]
B28: Total | E28: =SUM(E9:E27) | G28: =SUM(G9:G27) | H28: =SUM(H9:H27) | I28: =SUM(I9:I27) | J28: =SUM(J9:J27) | K28: =SUM(K9:K27) | M28: =SUM(M9:M27)

Sheet Inst Pressurizadas
B1: ='Levantamento Campo'!B1
B4: Circuito | E4: Gás Pressurizado | U4: Conexões
E5: Dutos | H5: Reguladores | M5: Válvulas | P5: Registros | S5: Reservatórios | U5: Tipo | V5: Joelhos | X5: Curva | Y5: Luvas | AA5: Tês | AC5: Junções
E6: DN | F6: h | G6: C | H6: DN | I6: Qtd | J6: Tipo | K6: Redução Pressão | M6: DN | N6: Qtd | O6: Tipo | P6: DN | Q6: Qtd | R6: Tipo | S6: Qtd | T6: Tipo | V6: 90° | W6: 45° | X6: 90° | Y6: Simples | Z6: Redução | AA6: Simples | AB6: Redução | AC6: 45° | AD6: Redução
E7: [mm] | F7: [cm] | G7: [m] | H7: [mm] | K7: de | L7: para | M7: [mm] | P7: [mm] | U7: DN
B17: Total | G17: =SUM(G8:G16) | I17: =SUM(I8:I16) | N17: =SUM(N8:N16) | Q17: =SUM(Q8:Q16) | S17: =SUM(S8:S16) | V17: =SUM(V7:V16) | W17: =SUM(W7:W16) | X17: =SUM(X7:X16) | Y17: =SUM(Y7:Y16) | Z17: =SUM(Z7:Z16) | AA17: =SUM(AA7:AA16) | AB17: =SUM(AB7:AB16) | AC17: =SUM(AC7:AC16) | AD17: =SUM(AD7:AD16)

Sheet Inst de Segurança
B1: ='Levantamento Campo'!B1
E4: Terminais | I4: Captação | N4: Equalização | P4: Aterramento
E5: Qtd | F5: Dimensões | I5: Barra | J5: Cordoalha | K5: Duto | L5: Terminal Compressão | M5: Fixação | N5: Cordoalha | O5: Grampo | P5: Haste | S5: Caixa Inspeção
B6: Ambiente | F6: L | G6: e | H6: C | P6: DN | Q6: C | R6: Qtd | S6: Qtd | T6: DN | U6: h
F7: [pol] | G7: [pol] | H7: [mm] | I7: [m] | J7: [m] | K7: [m] | P7: [pol] | Q7: [m] | T7: [pol] | U7: [mm]
B17: Total | E17: =SUM(E8:E16) | I17: =SUM(I8:I16) | J17: =SUM(J8:J16) | K17: =SUM(K8:K16) | L17: =SUM(L8:L16) | M17: =SUM(M8:M16) | N17: =SUM(N8:N16) | O17: =SUM(O8:O16) | Q17: =SUM(Q8:Q16) | R17: =SUM(R8:R16) | S17: =SUM(S8:S16)
J20: Hidrantes | X20: Conexões
E21: Extintores Portáteis | J21: Qtd | K21: Dimensões | N21: Visor | Q21: Duto de Contra Incêndio | T21: Registro | V21: Válvula | X21: Tipo | Y21: Joelhos | AA21: Curva | AB21: Luvas | AD21: Tês | AF21: Junções
B22: Ambiente | E22: Local | F22: Tipo | G22: Peso | H22: Cpcd Extint Mín | I22: Qtd | K22: L | L22: Prof | M22: h | N22: L | O22: e | P22: C | Q22: DN | R22: h | S22: C | T22: DN | U22: Qtd | V22: DN | W22: Qtd | Y22: 90° | Z22: 45° | AA22: 90° | AB22: Simples | AC22: Redução | AD22: Simples | AE22: Redução | AF22: 45° | AG22: Redução
G23: [KgF] | K23: [cm] | L23: [cm] | M23: [cm] | N23: [cm] | O23: [mm] | P23: [cm] | Q23: [pol] | R23: [cm] | S23: [m] | T23: [pol] | V23: [pol] | X23: DN
S33: =SUM(S24:S32)
S34: =SUM(S25:S33)
S35: =SUM(S26:S34)
S36: =SUM(S27:S35)
S37: =SUM(S28:S36)
S38: =SUM(S29:S37)
S39: =SUM(S30:S38)
S40: =SUM(S31:S39)
S41: =SUM(S32:S40)
S42: =SUM(S33:S41)
B43: Total | I43: =SUM(I24:I42) | J43: =SUM(J34:J42) | S43: =SUM(S34:S42) | U43: =SUM(U34:U42) | W43: =SUM(W34:W42) | Y43: =SUM(Y33:Y42) | Z43: =SUM(Z33:Z42) | AA43: =SUM(AA33:AA42) | AB43: =SUM(AB33:AB42) | AC43: =SUM(AC33:AC42) | AD43: =SUM(AD33:AD42) | AE43: =SUM(AE33:AE42) | AF43: =SUM(AF33:AF42) | AG43: =SUM(AG33:AG42)

Sheet Comunicações Ambientais
B1: ='Levantamento Campo'!B1
E4: Plaquetas | N4: Sinalização de Via
B5: Ambiente | E5: Local | F5: Saída | G5: Extintor | H5: Quadro Força | I5: Hidrante | J5: Alarme | K5: Proibido Fumar | L5: Perigo Inflamável | M5: Risco Explosão | N5: Contra Mão | O5: Curva Direita | P5: Curva Esquerda | Q5: 40 Km/h | R5: Pare
B27: Total | F27: =SUM(F7:F26) | G27: =SUM(G7:G26) | H27: =SUM(H7:H26) | I27: =SUM(I7:I26) | J27: =SUM(J7:J26) | K27: =SUM(K7:K26) | L27: =SUM(L7:L26) | M27: =SUM(M7:M26) | ... T27: =SUM(T7:T26)

Sheet Paisagismos
B1: ='Levantamento Campo'!B1
B5: Ambiente | C5: Local

Sheet Entrega da Obra
B1: ='Levantamento Campo'!B1

Sheet Instalacoes
B1: Instalações Elétricas - Local

Sheet Comunicacoes
B1: Ambiente | C1: Local | D1: Extintor
